<!-- 
    Model: Blobby
    Reference: Mujoco Humanoid.xml
-->
<mujoco model="Blobby">
    <option timestep="0.01" />

    <visual>
        <map force="0.1" zfar="30" />
        <rgba haze="0.15 0.25 0.35 1" />
        <global offwidth="2560" offheight="1440" elevation="-20" azimuth="0" />
    </visual>

    <statistic center="0 0 0.7" />

    <asset>
        <texture type="skybox" builtin="gradient" rgb1=".3 .5 .7" rgb2="0 0 0" width="32"
            height="512" />
        <texture name="body" type="cube" builtin="flat" mark="cross" width="127" height="1278"
            rgb1="0.8 0.6 0.4" rgb2="0.8 0.6 0.4" markrgb="1 1 1" random="0.01" />
        <material name="body" texture="body" texuniform="true" rgba="0.8 0.6 .4 1" />
        <texture name="grid" type="2d" builtin="checker" width="512" height="512" rgb1=".1 .2 .3"
            rgb2=".2 .3 .4" />
        <material name="grid" texture="grid" texrepeat="1 1" texuniform="true" reflectance=".2" />
    </asset>

    <default>
        <motor ctrlrange="-1 1" ctrllimited="true" />
        <!-- Blobby -->
        <default class="body">
            <!-- Geoms -->
            <default class = "shin">
                <geom type="capsule" size="0.07"/>
            </default>
            <!-- Joints -->
            <joint type="hinge" damping=".2" stiffness="1" armature=".01" limited="true"
                solimplimit="0 .99 .01" />
            <default class="joint_big">
                <joint damping="15" stiffness="10" />

                <default class="bthigh_xz">
                    <joint range="-30 30" />
                </default>
                <default class="bthigh_y">
                    <joint range="-40 40" />
                </default>
            </default>
            <default class="knee">
                <!-- <joint damping="15" stiffness="10" range="-40 40" /> -->
                <joint damping="15" stiffness="100" range="-1 1" />
            </default>
        </default>

        <!-- Food -->
        <default class="food">
            <geom type="capsule" size="0.11 0.08" />
            <site type="box" size="0.07 0.07 1.2" rgba="0.6 0.7 0.8 0.1"/>
        </default>

        <!-- Site -->
        <default class="site">
            <site type="box" size="0.05 0.05 0.03" rgba="0.6 0.7 0.8 0.1"/>
        </default>

        <!-- Motor -->
        <default class="blobby_motor">
            <motor gear="180" />
        </default>
    </default>

    <!-- World bodies -->
    <worldbody>
        <geom name="floor" size="0 0 .05" type="plane" material="grid" condim="3" />
        <light name="spotlight" mode="targetbodycom" target="blobby" diffuse=".8 .8 .8"
            specular="0.3 0.3 0.3" pos="0 -6 4" cutoff="30" />

        <!-- Blobby -->
        <body name="blobby" childclass="body" pos="0 0 0.6" euler="0 0 45">
            <light name="top" pos="0 0 2" mode="trackcom" />
            <camera name="back" pos="-3 0 1" xyaxes="0 -1 0 1 0 2" mode="trackcom" />
            <camera name="side" pos="0 -3 1" xyaxes="1 0 0 0 1 2" mode="trackcom" />

            <!-- Main body -->
            <freejoint name="root"/>
            <geom name="sphere" size="0.2" density="900"/>

            <body name="thigh1" pos="0.2 0 0">
                <!-- Horizontal joint -->
                <joint name="thigh1_xz" axis="0 0 1" class="bthigh_xz" />
                <!-- Vertical joint -->
                <joint name="thigh1_y" axis="0 -1 0" class="bthigh_y" />
                <geom name="thigh1" type="capsule" fromto="0 0 0 0.25 0 0" size="0.06" />
                <body name="shin1" pos="0.25 0 0">
                    <joint name="knee1" axis="0 -1 0" class="knee" />
                    <geom name="shin1" class="shin" fromto="0 0 0 0 0 -0.5"/>
                </body>
            </body>

            <body name="thigh2" pos="0 0.2 0">
                <joint name="thigh2_xz" axis="0 0 1" class="bthigh_xz" />
                <joint name="thigh2_y" axis="1 0 0" class="bthigh_y" />
                <geom name="thigh2" type="capsule" fromto="0 0 0 0 0.25 0" size="0.06" />
                <body name="shin2" pos="0 0.25 0">
                    <joint name="knee2" axis="1 0 0" class="knee" />
                    <geom name="shin2" class="shin" fromto="0 0 0 0 0 -0.5"/>
                </body>
            </body>

            <body name="thigh3" pos="-0.2 0 0">
                <joint name="thigh3_xz" axis="0 0 1" class="bthigh_xz" />
                <joint name="thigh3_y" axis="0 1 0" class="bthigh_y" />
                <geom name="thigh3" type="capsule" fromto="0 0 0 -0.25 0 0" size="0.06" />
                <body name="shin3" pos="-0.25 0 0">
                    <joint name="knee3" axis="0 1 0" class="knee" />
                    <geom name="shin3" class="shin" fromto="0 0 0 0 0 -0.5"/>
                </body>
            </body>

            <body name="thigh4" pos="0 -0.2 0">
                <joint name="thigh4_xz" axis="0 0 1" class="bthigh_xz" />
                <joint name="thigh4_y" axis="-1 0 0" class="bthigh_y" />
                <geom name="thigh4" type="capsule" fromto="0 0 0 0 -0.25 0" size="0.06" />
                <body name="shin4" pos="0 -0.25 0">
                    <joint name="knee4" axis="-1 0 0" class="knee" />
                    <geom name="shin4" class="shin" fromto="0 0 0 0 0 -0.5"/>
                </body>
            </body>

            <!-- <site name="sMain" pos="0 0 -0.21" class="site"/> -->
        </body>

        <!-- Other world bodies -->
        <body>
            <!-- Testing -->
            <!-- <geom name="food0" pos="0 0 0" size="0.05 0.1" class="food" />
            <geom name="foodA" pos="0.5 0 0" size="0.05 0.4" class="food" /> -->
            <!-- Geom food -->
            <geom name="food1" class="food" pos="0.6 0 0"/>
            <geom name="food2" class="food" pos="1 0 0"  />
            <geom name="food3" class="food" pos="2 0 0"  />
            <geom name="food4" class="food" pos="3 0 0"  />
            <geom name="food5" class="food" pos="4 0 0"  />
            <geom name="food6" class="food" pos="-3 0 0"  />
            <!-- Site food -->
            <!-- <site name="foodX" class="food" pos="0.3 0 0" /> -->
        </body>
    </worldbody>

    <!-- Sensors -->
    <sensor>
        <!-- <touch name="tMain" site="sMain" cutoff="1"/> -->
        <!-- <touch name="tFood1" site="foodX"/> -->
    </sensor>

    <!-- Controls -->
    <actuator>
        <!-- Thigh motor -->
        <motor name="thigh1_xz" class="blobby_motor" joint="thigh1_xz" />
        <motor name="thigh1_y"  class="blobby_motor" joint="thigh1_y" />
        <motor name="thigh2_xz" class="blobby_motor" joint="thigh2_xz" />
        <motor name="thigh2_y"  class="blobby_motor" joint="thigh2_y" />
        <motor name="thigh3_xz" class="blobby_motor" joint="thigh3_xz" />
        <motor name="thigh3_y"  class="blobby_motor" joint="thigh3_y" />
        <motor name="thigh4_xz" class="blobby_motor" joint="thigh4_xz" />
        <motor name="thigh4_y"  class="blobby_motor" joint="thigh4_y" />
        <!-- Knee motor -->
        <!-- <motor name="knee1"     class="blobby_motor" joint="knee1" /> -->
        <!-- <motor name="knee2"     class="blobby_motor" joint="knee2" /> -->
        <!-- <motor name="knee3"     class="blobby_motor" joint="knee3" /> -->
        <!-- <motor name="knee4"     class="blobby_motor" joint="knee4" /> -->
    </actuator>
</mujoco>